<?xml version="1.0" ?>

<robot name="Robotman" xmlns:xacro="http://www.ros.org/wiki/xacro">
  
  <!-- BGN - Include -->
  <xacro:include filename="$(find robotman_description)/urdf/links_joints.xacro" />
  <xacro:include filename="$(find robotman_description)/urdf/gazebo.xacro" />
  <!-- END - Include -->
  
  <material name="white">
    <color rgba="1 1 1 1"/>
  </material>

  <material name="black">
    <color rgba="0 0 0 1"/>
  </material>

  <material name="blue">
    <color rgba="0 0 1 1"/>
  </material>

  <!-- BGN - Robot description -->
  <m_link_mesh name="base_link"
              origin_rpy="1.5807 0 1.5807" origin_xyz="0 0 0.03"
              mass="5.0"
              ixx="1.3235" ixy="0" ixz="0"
              iyy="1.3235" iyz="0"
              izz="0.9655"
              material="white"
              meshfile="package://robotman_description/meshes/base.stl"
              meshscale="0.001 0.001 0.001" />
              
  <m_joint name="base_link__cuerpo" type="revolute"
           axis_xyz="0 1 0"
           origin_rpy="0 0 0" origin_xyz="0 0 0.1"
           parent="base_link" child="cuerpo"
           limit_e="10000" limit_l="-0.2618" limit_u="0.2618" limit_v="0.6" />
           
  <m_link_mesh name="cuerpo"
              origin_rpy="1.5807 0 1.5807" origin_xyz="0 0 0.60"
              mass="12.633"
              ixx="1.323" ixy="0" ixz="0"
              iyy="1.323" iyz="0"
              izz="0.965"
              material="white"
              meshfile="package://robotman_description/meshes/cuerpo.stl"
              meshscale="0.001 0.001 0.001" />
  
  <m_joint name="cuerpo__cabeza" type="revolute"
           axis_xyz="0 1 0"
           origin_rpy="0 0 0" origin_xyz="0 0 1.25"
           parent="cuerpo" child="cabeza"
           limit_e="1000" limit_l="0" limit_u="0.5" limit_v="0.5" />
           
  <m_link_mesh name="cabeza"
              origin_rpy="1.5807 0 1.5807" origin_xyz="0 0 0.0"
              mass="2.0"
              ixx="0.132" ixy="0" ixz="0"
              iyy="0.132" iyz="0"
              izz="0.097"
              material="white"
              meshfile="package://robotman_description/meshes/cabeza.stl"
              meshscale="0.001 0.001 0.001" />
  
  <m_joint name="cuerpo__brazo_derecho" type="revolute"
           axis_xyz="0 0 1"
           origin_rpy="-0.4 -0.1 0" origin_xyz="0.08 -0.55 0.06"
           parent="cuerpo" child="brazo_derecho"
           limit_e="1000" limit_l="-1.5807" limit_u="0" limit_v="0.5" />
           
  <m_link_mesh name="brazo_derecho"
              origin_rpy="1.5807 0 -1.5807" origin_xyz="0.0 0.0 0.35"
              mass="1.5"
              ixx="0.132" ixy="0" ixz="0"
              iyy="0.132" iyz="0"
              izz="0.097"
              material="white"
              meshfile="package://robotman_description/meshes/brazo_derecho.stl"
              meshscale="0.001 0.001 0.001" />
              
  <m_joint name="cuerpo__brazo_izquierdo" type="revolute"
           axis_xyz="0 0 1"
           origin_rpy="0.4 -0.1 0" origin_xyz="0.08 0.55 0.06"
           parent="cuerpo" child="brazo_izquierdo"
           limit_e="1000" limit_l="0" limit_u="1.5807" limit_v="0.5" />
           
  <m_link_mesh name="brazo_izquierdo"
              origin_rpy="1.5807 0 1.5807" origin_xyz="0.0 0.0 0.35"
              mass="1.5"
              ixx="0.132" ixy="0" ixz="0"
              iyy="0.132" iyz="0"
              izz="0.097"
              material="white"
              meshfile="package://robotman_description/meshes/brazo_izquierdo.stl"
              meshscale="0.001 0.001 0.001" />

  <joint name="cuerpo__ruedafrentederecha" type="continuous">
      <parent link="base_link"/>
      <child link="ruedafrentederecha"/>
      <origin xyz="0.21 -0.30 -0.05" rpy="0.0 0.0 0"/>
      <axis xyz="0 1 0"/>
  </joint>

  <m_link_mesh name="ruedafrentederecha"
              origin_rpy="1.5807 0 3.1416" origin_xyz="0 0 0"
              mass="2"
              ixx="0.132" ixy="0" ixz="0"
              iyy="0.132" iyz="0"
              izz="0.097"
              material="black"
              meshfile="package://robotman_description/meshes/Rueda.stl"
              meshscale="0.0009 0.0009 0.0009" />

  <joint name="cuerpo__ruedatraseraderecha" type="continuous">
      <parent link="base_link"/>
      <child link="ruedatraseraderecha"/>
      <origin xyz="-0.20 -0.30 -0.05" rpy="0.0 0.0 0"/>
      <axis xyz="0 1 0"/>
  </joint>

  <m_link_mesh name="ruedatraseraderecha"
              origin_rpy="1.5807 0 3.1416" origin_xyz="0 0 0"
              mass="2"
              ixx="0.132" ixy="0" ixz="0"
              iyy="0.132" iyz="0"
              izz="0.097"
              material="black"
              meshfile="package://robotman_description/meshes/Rueda.stl"
              meshscale="0.0009 0.0009 0.0009" />

  <joint name="cuerpo__ruedafrenteizquierda" type="continuous">
      <parent link="base_link"/>
      <child link="ruedafrenteizquierda"/>
      <origin xyz="0.21 0.30 -0.05" rpy="0.0 0.0 0"/>
      <axis xyz="0 1 0"/>
  </joint>

  <m_link_mesh name="ruedafrenteizquierda"
              origin_rpy="1.5807 0 3.1416" origin_xyz="0 0 0"
              mass="2"
              ixx="0.132" ixy="0" ixz="0"
              iyy="0.132" iyz="0"
              izz="0.097"
              material="black"
              meshfile="package://robotman_description/meshes/Rueda.stl"
              meshscale="0.0009 0.0009 0.0009" />

  <joint name="cuerpo__ruedatraseraizquierda" type="continuous">
      <parent link="base_link"/>
      <child link="ruedatraseraizquierda"/>
      <origin xyz="-0.20 0.30 -0.05" rpy="0.0 0.0 0"/>
      <axis xyz="0 1 0"/>
  </joint>

  <m_link_mesh name="ruedatraseraizquierda"
              origin_rpy="1.5807 0 3.1416" origin_xyz="0 0 0"
              mass="2"
              ixx="0.132" ixy="0" ixz="0"
              iyy="0.132" iyz="0"
              izz="0.097"
              material="black"
              meshfile="package://robotman_description/meshes/Rueda.stl"
              meshscale="0.0009 0.0009 0.0009" />

  <joint name="camera_joint" type="fixed">
    <axis xyz="0 1 0" />
    <origin xyz="0.115 0 0.105" rpy="0 0 0"/>
    <parent link="cabeza"/>
    <child link="camera_link"/>
  </joint>

  <!-- Head Camera -->
  <link name="camera_link">
    <collision>
      <origin xyz="0 0 0" rpy="0 0 0"/>
      <geometry>
        <box size="0.03 0.06 0.03"/>
      </geometry>
    </collision>

    <visual>
      <origin xyz="0 0 0" rpy="0 0 0"/>
      <geometry>
        <box size="0.03 0.06 0.03"/>
      </geometry>
      <material name="black"/>
    </visual>

    <inertial>
      <mass value="1e-5" />
      <origin xyz="0 0 0" rpy="0 0 0"/>
      <inertia ixx="1e-6" ixy="0" ixz="0" iyy="1e-6" iyz="0" izz="1e-6" />
    </inertial>
  </link>

  <joint name="rplaser_joint" type="fixed">
    <axis xyz="0 1 0" />
    <origin xyz="0.34 0 0.2" rpy="0 0 0"/>
    <parent link="base_link"/>
    <child link="rplidar_link"/>
  </joint>

  <!-- RPlaser Laser -->
  <link name="rplidar_link">
    <collision>
      <origin xyz="0 0 0" rpy="0 0 0"/>
      <geometry>
        <cylinder length="0.04" radius="0.05"/>
      </geometry>
    </collision>

    <visual>
      <origin xyz="0 0 0" rpy="0 0 0"/>
      <geometry>
	<cylinder length="0.04" radius="0.05"/>
      </geometry>
      <material name="blue"/>
    </visual>

    <inertial>
      <mass value="1e-5" />
      <origin xyz="0 0 0" rpy="0 0 0"/>
      <inertia ixx="1e-6" ixy="0" ixz="0" iyy="1e-6" iyz="0" izz="1e-6" />
    </inertial>
  </link>

  <joint name="depth_joint" type="fixed">
    <axis xyz="0 1 0" />
    <origin xyz="0.20 0 0.63" rpy="0 0 0"/>
    <parent link="cuerpo"/>
    <child link="depth_link"/>
  </joint>

  <!-- Depth Camera -->
  <link name="depth_link">
    <collision>
      <origin xyz="0 0 0" rpy="0 0 0"/>
      <geometry>
        <box size="0.03 0.11 0.03"/>
      </geometry>
    </collision>

    <visual>
      <origin xyz="0 0 0" rpy="0 0 0"/>
      <geometry>
        <box size="0.03 0.11 0.03"/>
      </geometry>
      <material name="blue"/>
    </visual>

    <inertial>
      <mass value="1e-5" />
      <origin xyz="0 0 0" rpy="0 0 0"/>
      <inertia ixx="1e-6" ixy="0" ixz="0" iyy="1e-6" iyz="0" izz="1e-6" />
    </inertial>
  </link>

  <joint name="screen_joint" type="fixed">
    <axis xyz="0 1 0" />
    <origin xyz="0.14 0.00 0.88" rpy="0.00 1.38 0.00"/>
    <parent link="cuerpo"/>
    <child link="screen_link"/>
  </joint>

  <!-- Screen Camera -->
  <link name="screen_link">
    <collision>
      <origin xyz="0 0 0" rpy="0 0 1.5708"/>
      <geometry>
        <box size="0.26 0.20 0.03"/>
      </geometry>
    </collision>

    <visual>
      <origin xyz="0 0 0" rpy="0 0 1.5708"/>
      <geometry>
        <box size="0.26 0.20 0.03"/>
      </geometry>
      <material name="black"/>
    </visual>

    <inertial>
      <mass value="1e-5" />
      <origin xyz="0 0 0" rpy="0 0 0"/>
      <inertia ixx="1e-6" ixy="0" ixz="0" iyy="1e-6" iyz="0" izz="1e-6" />
    </inertial>
  </link>

  <joint name="eye_left_joint" type="fixed">
    <axis xyz="0 1 0" />
    <origin xyz="0.05 0.06 0.0" rpy="0.00 0.00 0.00"/>
    <parent link="cabeza"/>
    <child link="eye_left_link"/>
  </joint>

  <!-- Left Eye Camera -->
  <link name="eye_left_link">
    <collision>
      <origin xyz="0 0 0" rpy="0 0 0"/>
      <geometry>
        <box size="0.02 0.06 0.06"/>
      </geometry>
    </collision>

    <visual>
      <origin xyz="0 0 0" rpy="0 0 0"/>
      <geometry>
        <box size="0.02 0.06 0.06"/>
      </geometry>
      <material name="black"/>
    </visual>

    <inertial>
      <mass value="1e-5" />
      <origin xyz="0 0 0" rpy="0 0 0"/>
      <inertia ixx="1e-6" ixy="0" ixz="0" iyy="1e-6" iyz="0" izz="1e-6" />
    </inertial>
  </link>


</robot>
